Workbook

Sheet AHMAD HQ — DASHBOARD
A1: AHMAD HQ — OPERATING HOME
A5: =HYPERLINK("https://docs.google.com/spreadsheets/d/1_zaAT-zqEQhwTW2ZNRLSnH8Peed7zZTzi3kd0RUHQRQ/edit#gid=1238984194","MONTH PLAN\nOutcomes • calendar • close") -> MONTH PLAN\nOutcomes • calendar • close | C5: =HYPERLINK("https://docs.google.com/spreadsheets/d/1_zaAT-zqEQhwTW2ZNRLSnH8Peed7zZTzi3kd0RUHQRQ/edit#gid=2011001001","THIS WEEK\nCommitments • deadlines") -> THIS WEEK\nCommitments • deadlines | E5: =HYPERLINK("https://docs.google.com/spreadsheets/d/1_zaAT-zqEQhwTW2ZNRLSnH8Peed7zZTzi3kd0RUHQRQ/edit#gid=407341757","EDIBLE\nStore pulse • controls") -> EDIBLE\nStore pulse • controls | G5: =HYPERLINK("https://docs.google.com/spreadsheets/d/1_zaAT-zqEQhwTW2ZNRLSnH8Peed7zZTzi3kd0RUHQRQ/edit#gid=1338168960","GARDENIA'S\nLaunch • sales funnel") -> GARDENIA'S\nLaunch • sales funnel | I5: =HYPERLINK("https://docs.google.com/spreadsheets/d/1_zaAT-zqEQhwTW2ZNRLSnH8Peed7zZTzi3kd0RUHQRQ/edit#gid=1651640479","CALLS / FOLLOW-UP\nContacts • next touch") -> CALLS / FOLLOW-UP\nContacts • next touch | K5: =HYPERLINK("https://docs.google.com/spreadsheets/d/1_zaAT-zqEQhwTW2ZNRLSnH8Peed7zZTzi3kd0RUHQRQ/edit#gid=2011001003","PEOPLE\nSchedule • capacity") -> PEOPLE\nSchedule • capacity
A8: MANAGEMENT PULSE — WHAT NEEDS ATTENTION
F9: SUN | G9: MON | H9: TUE | I9: WED | J9: THU | K9: FRI | L9: SAT
A10: ="CRITICAL MOVES\n"&COUNTIFS('WORK DESK — UPDATE'!G:G,"Yes",'WORK DESK — UPDATE'!J:J,"<>Done",'WORK DESK — UPDATE'!J:J,"<>Dropped")&" open" -> CRITICAL MOVES\n6 open | C10: ="WAITING / BLOCKED\n"&(COUNTIF('WORK DESK — UPDATE'!J:J,"Waiting")+COUNTIF('WORK DESK — UPDATE'!J:J,"Blocked"))&" items" -> WAITING / BLOCKED\n0 items | E10: ="DECISIONS\n"&COUNTIF('06_DECISIONS'!G:G,"Open") -> DECISIONS\n1 | F10: 30 | G10: 31 | H10: 1 | I10: 2 | J10: 3 | K10: 4 | L10: 5
F11: 6 | G11: 7 | H11: 8 | I11: 9 | J11: 10 | K11: 11 | L11: 12
F12: 13 | G12: 14 | H12: 15 | I12: 16 | J12: 17 | K12: 18 | L12: 19
F13: 20 | G13: 21 | H13: 22 | I13: 23 | J13: 24 | K13: 25 | L13: 26
F14: 27 | G14: 28 | H14: 29 | I14: 30 | J14: 1 | K14: 2 | L14: 3
A16: THIS WEEK — 6 MEANINGFUL MOVES
A17: FUNCTION / PROJECT | B17: WHAT MUST HAPPEN | C17: OWNER | D17: DUE | E17: STATUS | F17: WHY / RESULT | G17: WAITING / ESCALATE
A18: =IFERROR(__xludf.DUMMYFUNCTION("IFERROR(FILTER(HSTACK('WORK DESK — UPDATE'!B6:B120,'WORK DESK — UPDATE'!C6:C120,'WORK DESK — UPDATE'!D6:D120,'WORK DESK — UPDATE'!I6:I120,'WORK DESK — UPDATE'!J6:J120,'WORK DESK — UPDATE'!S6:S120,'WORK DESK — UPDATE'!K6:K120&IF('WORK DESK — UPDATE'!Q6:Q12"&"0=""Yes"","" • ESCALATE"","""")),'WORK DESK — UPDATE'!G6:G120=""Yes"",'WORK DESK — UPDATE'!J6:J120<>""Done"",'WORK DESK — UPDATE'!J6:J120<>""Dropped""),""No open critical moves"")"),"Gardenia's Fire") -> Gardenia's Fire | B18: =IFERROR(__xludf.DUMMYFUNCTION("""COMPUTED_VALUE"""),"Confirm sellable offer is ready from Emmanuel's real-life process; capture only price/cost/margin or constraints needed for selling/management") -> Confirm sellable offer is ready from Emmanuel's real-life process; capture only price/cost/margin or constraints needed for selling/management | C18: =IFERROR(__xludf.DUMMYFUNCTION("""COMPUTED_VALUE"""),"Emmanuel") -> Emmanuel | D18: =IFERROR(__xludf.DUMMYFUNCTION("""COMPUTED_VALUE"""),46265.0) -> 46265 | E18: =IFERROR(__xludf.DUMMYFUNCTION("""COMPUTED_VALUE"""),"In Progress") -> In Progress | F18: =IFERROR(__xludf.DUMMYFUNCTION("""COMPUTED_VALUE"""),"Sales readiness / management economics without duplicating product development") -> Sales readiness / management economics without duplicating product development | G18: =IFERROR(__xludf.DUMMYFUNCTION("""COMPUTED_VALUE"""),"")
A19: =IFERROR(__xludf.DUMMYFUNCTION("""COMPUTED_VALUE"""),"Gardenia's Fire") -> Gardenia's Fire | B19: =IFERROR(__xludf.DUMMYFUNCTION("""COMPUTED_VALUE"""),"Build/confirm target account list") -> Build/confirm target account list | C19: =IFERROR(__xludf.DUMMYFUNCTION("""COMPUTED_VALUE"""),"Emmanuel") -> Emmanuel | D19: =IFERROR(__xludf.DUMMYFUNCTION("""COMPUTED_VALUE"""),46266.0) -> 46266 | E19: =IFERROR(__xludf.DUMMYFUNCTION("""COMPUTED_VALUE"""),"Open") -> Open | F19: =IFERROR(__xludf.DUMMYFUNCTION("""COMPUTED_VALUE"""),"Create qualified sales pipeline") -> Create qualified sales pipeline | G19: =IFERROR(__xludf.DUMMYFUNCTION("""COMPUTED_VALUE"""),"")
A20: =IFERROR(__xludf.DUMMYFUNCTION("""COMPUTED_VALUE"""),"Gardenia's Fire") -> Gardenia's Fire | B20: =IFERROR(__xludf.DUMMYFUNCTION("""COMPUTED_VALUE"""),"Begin outreach and schedule tastings") -> Begin outreach and schedule tastings | C20: =IFERROR(__xludf.DUMMYFUNCTION("""COMPUTED_VALUE"""),"Emmanuel") -> Emmanuel | D20: =IFERROR(__xludf.DUMMYFUNCTION("""COMPUTED_VALUE"""),46269.0) -> 46269 | E20: =IFERROR(__xludf.DUMMYFUNCTION("""COMPUTED_VALUE"""),"Open") -> Open | F20: =IFERROR(__xludf.DUMMYFUNCTION("""COMPUTED_VALUE"""),"Create tastings / standing-account conversations") -> Create tastings / standing-account conversations | G20: =IFERROR(__xludf.DUMMYFUNCTION("""COMPUTED_VALUE"""),"")
A21: =IFERROR(__xludf.DUMMYFUNCTION("""COMPUTED_VALUE"""),"Edible Operations") -> Edible Operations | B21: =IFERROR(__xludf.DUMMYFUNCTION("""COMPUTED_VALUE"""),"Execute labor schedule correction and verify effect") -> Execute labor schedule correction and verify effect | C21: =IFERROR(__xludf.DUMMYFUNCTION("""COMPUTED_VALUE"""),"Emmanuel") -> Emmanuel | D21: =IFERROR(__xludf.DUMMYFUNCTION("""COMPUTED_VALUE"""),46267.0) -> 46267 | E21: =IFERROR(__xludf.DUMMYFUNCTION("""COMPUTED_VALUE"""),"In Progress") -> In Progress | F21: =IFERROR(__xludf.DUMMYFUNCTION("""COMPUTED_VALUE"""),"Bring labor productivity toward target") -> Bring labor productivity toward target | G21: =IFERROR(__xludf.DUMMYFUNCTION("""COMPUTED_VALUE""")," • ESCALATE") -> • ESCALATE
A22: =IFERROR(__xludf.DUMMYFUNCTION("""COMPUTED_VALUE"""),"Finance & Office") -> Finance & Office | B22: =IFERROR(__xludf.DUMMYFUNCTION("""COMPUTED_VALUE"""),"Confirm books/reconciliations/evidence current for weekly close") -> Confirm books/reconciliations/evidence current for weekly close | C22: =IFERROR(__xludf.DUMMYFUNCTION("""COMPUTED_VALUE"""),"Moises") -> Moises | D22: =IFERROR(__xludf.DUMMYFUNCTION("""COMPUTED_VALUE"""),46269.0) -> 46269 | E22: =IFERROR(__xludf.DUMMYFUNCTION("""COMPUTED_VALUE"""),"Open") -> Open | F22: =IFERROR(__xludf.DUMMYFUNCTION("""COMPUTED_VALUE"""),"Reliable finance close / no silent issue") -> Reliable finance close / no silent issue | G22: =IFERROR(__xludf.DUMMYFUNCTION("""COMPUTED_VALUE""")," • ESCALATE") -> • ESCALATE
A23: =IFERROR(__xludf.DUMMYFUNCTION("""COMPUTED_VALUE"""),"My Work") -> My Work | B23: =IFERROR(__xludf.DUMMYFUNCTION("""COMPUTED_VALUE"""),"xfgnxfm") -> xfgnxfm | C23: =IFERROR(__xludf.DUMMYFUNCTION("""COMPUTED_VALUE"""),"xfmfhm") -> xfmfhm | D23: =IFERROR(__xludf.DUMMYFUNCTION("""COMPUTED_VALUE"""),"xmh") -> xmh | E23: =IFERROR(__xludf.DUMMYFUNCTION("""COMPUTED_VALUE"""),"Open") -> Open | F23: =IFERROR(__xludf.DUMMYFUNCTION("""COMPUTED_VALUE"""),"xfmhxfhm") -> xfmhxfhm | G23: =IFERROR(__xludf.DUMMYFUNCTION("""COMPUTED_VALUE"""),"")
A29: OPERATING AREAS — PURPOSE • CURRENT STATE • WHAT'S NEXT
A30: AREA | B30: FOCUS | C30: OWNER | D30: PURPOSE / OUTCOME | E30: CURRENT MILESTONE | F30: WHAT'S NEXT | G30: STATUS
A31: =IFERROR(__xludf.DUMMYFUNCTION("IFERROR(FILTER(HSTACK('02_PROJECTS_FUNCTIONS'!A2:A120,'02_PROJECTS_FUNCTIONS'!C2:C120,'02_PROJECTS_FUNCTIONS'!D2:D120,'02_PROJECTS_FUNCTIONS'!E2:E120,'02_PROJECTS_FUNCTIONS'!F2:F120,'02_PROJECTS_FUNCTIONS'!H2:H120,'02_PROJECTS_FUNCTIONS'!J2:J120),'02_PROJ"&"ECTS_FUNCTIONS'!A2:A120<>""""),"""")"),"Edible Operations") -> Edible Operations | B31: =IFERROR(__xludf.DUMMYFUNCTION("""COMPUTED_VALUE"""),"MAINTAIN") -> MAINTAIN | C31: =IFERROR(__xludf.DUMMYFUNCTION("""COMPUTED_VALUE"""),"Emmanuel") -> Emmanuel | D31: =IFERROR(__xludf.DUMMYFUNCTION("""COMPUTED_VALUE"""),"Keep store stable while correcting sales/labor/service economics") -> Keep store stable while correcting sales/labor/service economics | E31: =IFERROR(__xludf.DUMMYFUNCTION("""COMPUTED_VALUE"""),"Correct current sales/labor trend") -> Correct current sales/labor trend | F31: =IFERROR(__xludf.DUMMYFUNCTION("""COMPUTED_VALUE"""),"Verify schedule/lead behavior effect") -> Verify schedule/lead behavior effect | G31: =IFERROR(__xludf.DUMMYFUNCTION("""COMPUTED_VALUE"""),"Active") -> Active
A32: =IFERROR(__xludf.DUMMYFUNCTION("""COMPUTED_VALUE"""),"Gardenia's Fire") -> Gardenia's Fire | B32: =IFERROR(__xludf.DUMMYFUNCTION("""COMPUTED_VALUE"""),"PUSH") -> PUSH | C32: =IFERROR(__xludf.DUMMYFUNCTION("""COMPUTED_VALUE"""),"Emmanuel") -> Emmanuel | D32: =IFERROR(__xludf.DUMMYFUNCTION("""COMPUTED_VALUE"""),"Prove offer and create repeatable local corporate standing-order sales") -> Prove offer and create repeatable local corporate standing-order sales | E32: =IFERROR(__xludf.DUMMYFUNCTION("""COMPUTED_VALUE"""),"Product proof + outreach/tastings") -> Product proof + outreach/tastings | F32: =IFERROR(__xludf.DUMMYFUNCTION("""COMPUTED_VALUE"""),"Finalize costing, target list, outreach, tastings") -> Finalize costing, target list, outreach, tastings | G32: =IFERROR(__xludf.DUMMYFUNCTION("""COMPUTED_VALUE"""),"Active") -> Active
A33: =IFERROR(__xludf.DUMMYFUNCTION("""COMPUTED_VALUE"""),"Finance & Office") -> Finance & Office | B33: =IFERROR(__xludf.DUMMYFUNCTION("""COMPUTED_VALUE"""),"PUSH") -> PUSH | C33: =IFERROR(__xludf.DUMMYFUNCTION("""COMPUTED_VALUE"""),"Moises") -> Moises | D33: =IFERROR(__xludf.DUMMYFUNCTION("""COMPUTED_VALUE"""),"Keep books, cash, obligations, evidence, and office controls current") -> Keep books, cash, obligations, evidence, and office controls current | E33: =IFERROR(__xludf.DUMMYFUNCTION("""COMPUTED_VALUE"""),"Reliable weekly close / exceptions") -> Reliable weekly close / exceptions | F33: =IFERROR(__xludf.DUMMYFUNCTION("""COMPUTED_VALUE"""),"Establish clean weekly close with evidence") -> Establish clean weekly close with evidence | G33: =IFERROR(__xludf.DUMMYFUNCTION("""COMPUTED_VALUE"""),"Active") -> Active
A34: =IFERROR(__xludf.DUMMYFUNCTION("""COMPUTED_VALUE"""),"Podcast / Legacy") -> Podcast / Legacy | B34: =IFERROR(__xludf.DUMMYFUNCTION("""COMPUTED_VALUE"""),"PUSH") -> PUSH | C34: =IFERROR(__xludf.DUMMYFUNCTION("""COMPUTED_VALUE"""),"Ahmad") -> Ahmad | D34: =IFERROR(__xludf.DUMMYFUNCTION("""COMPUTED_VALUE"""),"Create and publish meaningful podcast/video work while retaining legacy material") -> Create and publish meaningful podcast/video work while retaining legacy material | E34: =IFERROR(__xludf.DUMMYFUNCTION("""COMPUTED_VALUE"""),"Current episode/video progression") -> Current episode/video progression | F34: =IFERROR(__xludf.DUMMYFUNCTION("""COMPUTED_VALUE"""),"Move next video/episode to executable step") -> Move next video/episode to executable step | G34: =IFERROR(__xludf.DUMMYFUNCTION("""COMPUTED_VALUE"""),"Active") -> Active
A35: =IFERROR(__xludf.DUMMYFUNCTION("""COMPUTED_VALUE"""),"People / Systems") -> People / Systems | B35: =IFERROR(__xludf.DUMMYFUNCTION("""COMPUTED_VALUE"""),"MAINTAIN") -> MAINTAIN | C35: =IFERROR(__xludf.DUMMYFUNCTION("""COMPUTED_VALUE"""),"Emmanuel") -> Emmanuel | D35: =IFERROR(__xludf.DUMMYFUNCTION("""COMPUTED_VALUE"""),"Clear ownership, capacity, follow-through, and system improvement") -> Clear ownership, capacity, follow-through, and system improvement | E35: =IFERROR(__xludf.DUMMYFUNCTION("""COMPUTED_VALUE"""),"Monday-ready operating rhythm") -> Monday-ready operating rhythm | F35: =IFERROR(__xludf.DUMMYFUNCTION("""COMPUTED_VALUE"""),"Operate Phase 1 and remove duplicate reporting") -> Operate Phase 1 and remove duplicate reporting | G35: =IFERROR(__xludf.DUMMYFUNCTION("""COMPUTED_VALUE"""),"Active") -> Active
A36: =IFERROR(__xludf.DUMMYFUNCTION("""COMPUTED_VALUE"""),"Iron Marks / Iron March") -> Iron Marks / Iron March | B36: =IFERROR(__xludf.DUMMYFUNCTION("""COMPUTED_VALUE"""),"PARK") -> PARK | C36: =IFERROR(__xludf.DUMMYFUNCTION("""COMPUTED_VALUE"""),"TBD") -> TBD | D36: =IFERROR(__xludf.DUMMYFUNCTION("""COMPUTED_VALUE"""),"Keep visible without stealing capacity until intentionally activated") -> Keep visible without stealing capacity until intentionally activated | E36: =IFERROR(__xludf.DUMMYFUNCTION("""COMPUTED_VALUE"""),"Define offer/owner/test/capacity before PUSH") -> Define offer/owner/test/capacity before PUSH | F36: =IFERROR(__xludf.DUMMYFUNCTION("""COMPUTED_VALUE"""),"Remain parked until activation decision") -> Remain parked until activation decision | G36: =IFERROR(__xludf.DUMMYFUNCTION("""COMPUTED_VALUE"""),"Parked") -> Parked
A37: =IFERROR(__xludf.DUMMYFUNCTION("""COMPUTED_VALUE"""),"Ahmad Personal Finance / Life") -> Ahmad Personal Finance / Life | B37: =IFERROR(__xludf.DUMMYFUNCTION("""COMPUTED_VALUE"""),"PUSH") -> PUSH | C37: =IFERROR(__xludf.DUMMYFUNCTION("""COMPUTED_VALUE"""),"Ahmad / Moises / Emmanuel") -> Ahmad / Moises / Emmanuel | D37: =IFERROR(__xludf.DUMMYFUNCTION("""COMPUTED_VALUE"""),"Protect personal stability: money in/out, obligations, credit, personal admin, decisions") -> Protect personal stability: money in/out, obligations, credit, personal admin, decisions | E37: =IFERROR(__xludf.DUMMYFUNCTION("""COMPUTED_VALUE"""),"Basic visibility + recurring control") -> Basic visibility + recurring control | F37: =IFERROR(__xludf.DUMMYFUNCTION("""COMPUTED_VALUE"""),"Moises maintains back-end; Emmanuel coordinates completeness/exceptions; Ahmad decides") -> Moises maintains back-end; Emmanuel coordinates completeness/exceptions; Ahmad decides | G37: =IFERROR(__xludf.DUMMYFUNCTION("""COMPUTED_VALUE"""),"Build") -> Build
A43: QUICK DOORS — WORK FROM HERE, DON'T HUNT FOR FILES
A45: =HYPERLINK("https://docs.google.com/spreadsheets/d/1_qBjYd0F4BYYTxLMJjEZbQynBdHH5JGe83-U7nheJOE/edit?usp=drivesdk","EDIBLE DETAIL\nDaily • weekly • month close") -> EDIBLE DETAIL\nDaily • weekly • month close | D45: =HYPERLINK("https://docs.google.com/spreadsheets/d/1zrY3SOQiF2g8A_7z4ynA9mVnM7_qsvS8eBsebBRplmc/edit?usp=drivesdk","FINANCE DETAIL\nBooks • reconciliations • evidence") -> FINANCE DETAIL\nBooks • reconciliations • evidence | G45: =HYPERLINK("https://drive.google.com/drive/folders/1-CWhZsNUR2dnbbCLLOInkSOOHtFU_utm","GARDENIA'S FILES\nPlan • products • target lists") -> GARDENIA'S FILES\nPlan • products • target lists | J45: =HYPERLINK("https://docs.google.com/presentation/d/1Va2UIkSWL0s5wOi7MNcl7xbQONg7kE3dKpRRxlfgBCk/edit?usp=drivesdk","v3 BOARD\nPresentation reference") -> v3 BOARD\nPresentation reference

Sheet HQ_PLANS
A1: Plan ID | B1: Period Type | C1: Period Key | D1: Business / Area | E1: Objective / Priority | F1: Critical Move? | G1: Lead Behavior | H1: Lead Behavior Actual | I1: Expected Outcome | J1: Owner | K1: Due | L1: Status | M1: Result | N1: Evidence / Source

Sheet HQ_REGISTRIES
A1: Registry Type | B1: Business / Area | C1: Name | D1: Purpose / Responsibility | E1: Owner | F1: Cadence / Stage | G1: Status | H1: Backup / Contact | I1: Source / Evidence | J1: Notes

Sheet HQ_PEOPLE
A1: Name | B1: Email | C1: Role | D1: Function / Area | E1: Availability | F1: Responsibilities | G1: Backup | H1: Priority Load | I1: Coverage Status | J1: Training Status | K1: Active? | L1: Notes

Sheet HQ_REQUESTS
A1: Request ID | B1: Date | C1: Business / Area | D1: Request Type | E1: Request / Issue | F1: Severity / Urgency | G1: Owner | H1: Approval Status | I1: Status | J1: Due | K1: Evidence / Photo | L1: Resolution

Sheet HQ_SOURCE_MAP
A1: Business / Area | B1: Metric / Control | C1: Input Owner | D1: Authoritative Source | E1: Frequency | F1: Evidence Location | G1: Calculation / Rule | H1: Destination Screen | I1: Status | J1: Last Verified
A2: Shared Management | B2: Weekly priorities / Critical Moves / owned work | C2: Emmanuel | D2: AHMAD HQ — WORK DESK — UPDATE + THIS WEEK | E2: Weekly / live | F2: https://docs.google.com/spreadsheets/d/1_zaAT-zqEQhwTW2ZNRLSnH8Peed7zZTzi3kd0RUHQRQ/edit | G2: One management work record carries owner, due, status, result, evidence, blocker and escalation; role views compress from it. | H2: THIS WEEK; EMMANUEL — HOME; AHMAD — CONTROL | I2: VERIFIED INTERNAL MANAGEMENT SOURCE | J2: 2026-09-01
A3: Finance & Office | B3: Weekly finance close / control status / exceptions | C3: Moises | D3: OFFICE FINANCE — LIVE CONTROL SYSTEM — REVISED Aug 2026 | E3: Weekly | F3: https://docs.google.com/spreadsheets/d/1zrY3SOQiF2g8A_7z4ynA9mVnM7_qsvS8eBsebBRplmc/edit | G3: Weekly Review + Evidence Register + underlying account detail; one completion should feed management review, not parallel duplicate checkmarks. | H3: MOISES — HOME; HQ_CHECKLIST_RUNS; RESULTS & EXCEPTIONS | I3: VERIFIED STRUCTURE / LIVE USE EARLY | J3: 2026-09-01
A4: Finance & Office | B4: Books current / cash / A-P / A-R / payroll / reconciliations | C4: Moises | D4: QuickBooks + banks/cards/merchant/payroll source systems; Finance control workbook is management-control layer | E4: Weekly / monthly | F4: Finance control workbook + linked evidence/Drive | G4: Actuals must reconcile to transactional source; HQ receives current-through date, status, variance, exception and material decision. | H4: HQ_KSI; HQ_TARGETS; MOISES — HOME; AHMAD — CONTROL | I4: SOURCE ROLE VERIFIED / CONNECTION NOT YET VERIFIED | J4: 2026-09-01
A5: Edible | B5: Store operating controls / Week Close / operational exceptions | C5: Store Lead → Emmanuel | D5: Edible Hackensack — Store Operations Control System — v3 — Aug 2026 | E5: Daily / weekly / monthly | F5: https://docs.google.com/spreadsheets/d/1_qBjYd0F4BYYTxLMJjEZbQynBdHH5JGe83-U7nheJOE/edit | G5: Detailed work stays in Edible operating system; Week Close/results/exceptions roll upward; HQ is not a second store checklist. | H5: EDIBLE — OPERATE; HQ_CHECKLIST_RUNS; RESULTS & EXCEPTIONS | I5: VERIFIED STRUCTURE / ADOPTION EARLY | J5: 2026-09-01
A6: Edible | B6: Sales / orders / average ticket | C6: Emmanuel / Store | D6: Edible franchise/POS source; weekly management report is current reporting layer | E6: Weekly | F6: https://docs.google.com/spreadsheets/d/1Y1auf1Xc_wzNI4vh90JABYfC7HoifdcC/edit | G6: POS is transactional truth; management report/HQ must preserve week, comparable period, actual, target and variance. | H6: EDIBLE — OPERATE; HQ_TARGETS; HQ_KSI | I6: REPORT SOURCE VERIFIED / POS CONNECTION NOT VERIFIED | J6: 2026-09-01
A7: Edible | B7: Labor / COGS / waste / refunds | C7: Emmanuel + Moises | D7: Payroll/timeclock + POS/franchise + accounting sources; Edible KPI/Week Close is management layer | E7: Weekly | F7: Edible v3 + Finance evidence | G7: Use source actuals; compare to target; exception when materially outside standard; preserve cause/action. | H7: EDIBLE — OPERATE; HQ_KSI; RESULTS & EXCEPTIONS | I7: SOURCE MODEL VERIFIED / WIRING NOT VERIFIED | J7: 2026-09-01
A8: Gardenia's Fire | B8: Launch priorities / field activity / weekly conversion learning | C8: Emmanuel | D8: HQ Work Desk + Month Plan + Emmanuel weekly/September operating control | E8: Daily / weekly | F8: AHMAD HQ Phase 1 Core + current operating schedule/control materials | G8: Plan work in HQ; field execution produces coded outcomes, owner/date, follow-up, conversion learning and next move. | H8: GARDENIA — OPERATE; THIS WEEK; EMMANUEL — HOME | I8: VERIFIED MANAGEMENT SOURCE / LIVE SALES DATA EARLY | J8: 2026-09-01
A9: Gardenia's Fire | B9: Prospects / contacts / tastings / proposals / standing-account pipeline | C9: Emmanuel / revenue owner | D9: Shopify planned commerce/order/customer source + accounting for financial truth; Emmanuel's real-life operating process owns product development/testing | E9: Live / weekly / monthly | F9: Shopify/QuickBooks once configured; real-life operating evidence until then | G9: Commerce/accounting own transactions and financial truth; Emmanuel's operating process owns product development. HQ receives sellable-readiness state, revenue, orders, repeat/standing accounts, decision-useful margin/capacity, exceptions and decisions. | H9: GARDENIA — OPERATE; HQ_TARGETS; HQ_KSI; AHMAD — CONTROL | I9: PLANNED SOURCE / PRODUCT-DEVELOPMENT BOUNDARY CORRECTED | J9: 2026-09-03
A10: Gardenia's Fire | B10: Orders / standing cadence / revenue / repeat / margin | C10: Emmanuel + Moises | D10: Shopify planned commerce/order/customer source + accounting for financial truth | E10: Live / weekly / monthly | F10: Shopify/QuickBooks once configured; HQ product/costing currently interim | G10: Commerce system owns transactions; HQ receives revenue, orders, repeat/standing accounts, margin and exceptions. | H10: GARDENIA — OPERATE; HQ_TARGETS; HQ_KSI; AHMAD — CONTROL | I10: PLANNED SOURCE / NOT READY | J10: 2026-09-01
A11: Ironmark | B11: Pilot lane / providers / leads / completed jobs / economics / quality | C11: Emmanuel / assigned revenue owner | D11: Actual schedules/payroll/HR source where applicable; PEOPLE & CAPACITY is management snapshot; HQ_ACCESS is permission truth; HQ_PEOPLE only for consequential role/coverage state if needed | E11: Weekly / on change | F11: Authoritative schedule/HR source + AHMAD HQ Phase 1 Core | G11: Do not maintain a duplicate full roster/schedule in HQ. Surface only role ownership, current capacity/conflict, backup/coverage, material availability change and management exception. | H11: PEOPLE & CAPACITY; role Homes; HQ_ACCESS | I11: BOUNDARY CORRECTED — MANAGEMENT SNAPSHOT, NOT HR/SCHEDULE SYSTEM | J11: 2026-09-03
A12: People & Systems | B12: Role access / management depth / current capacity | C12: Emmanuel | D12: HQ_ACCESS + PEOPLE & CAPACITY; HQ_PEOPLE is intended durable people register | E12: Weekly / on change | F12: AHMAD HQ Phase 1 Core | G12: Separate confirmed roles/capacity from provisional roles; permissions must match management level and sensitive-area restrictions. | H12: PEOPLE & CAPACITY; role Homes; HQ_ACCESS | I12: PARTIAL / HQ_PEOPLE NOT POPULATED | J12: 2026-09-01
... A14: Personal / Ahmad | B14: Bills / obligations / recurring charges / deadlines / material exceptions | C14: Moises + Emmanuel | D14: Bank/provider/account sources + Drive evidence; HQ_PERSONAL_REGISTER is management-control layer | E14: Weekly | F14: Source map/evidence still to be established | G14: Do not recreate bookkeeping; surface upcoming obligations, money movement, deadlines, exceptions and decisions to Ahmad. | H14: AHMAD — CONTROL; MOISES — HOME; HQ_PERSONAL_REGISTER | I14: NOT YET POPULATED / SOURCE VERIFICATION REQUIRED | J14: 2026-09-01

Sheet HQ_REFERENCE_LIBRARY
A1: Business / Area | B1: Reference Type | C1: Title | D1: Current? | E1: Audience / Role | F1: Owner | G1: Source / Drive Link | H1: Supersedes / Replaces | I1: Status | J1: Notes

Sheet HQ_TRAINING
A1: Business / Area | B1: Role / Person | C1: Capability / Training | D1: Required? | E1: Status | F1: Evidence / Guide | G1: Owner | H1: Due | I1: Last Verified | J1: Notes

Sheet HQ_FINANCE_REGISTER
A1: Register Type | B1: Entity / Property | C1: Account / Policy / Vendor / Tax | D1: Status | E1: Amount / Balance | F1: Effective / Filing / Renewal | G1: Due / Next Date | H1: Owner | I1: Source / Evidence | J1: Next Action | K1: Notes
A2: Credit Line | B2: EA Hackensack | C2: Chase LOC | D2: STALE / RECONCILE REQUIRED | E2: 121412.5 | F2: Source dated 2025-09-25 | G2: Verify now | H2: Moises | I2: Balances (Updated 01.01.26) — EA HACKENSACK tab | J2: Reconcile to Chase documents + QuickBooks + current statement | K2: Working balance only; Chase litigation/credit-line correspondence now active.
A3: Credit Card | B3: EA Hackensack | C3: Chase card | D3: STALE / RECONCILE REQUIRED | E3: 15243.55 | F3: Source dated 2025-09-25 | G3: Verify now | H3: Moises | I3: Balances (Updated 01.01.26) — EA HACKENSACK tab | J3: Reconcile to card statement + QuickBooks | K3: Working balance.
A4: A/P | B4: EA Hackensack | C4: Plainfield Produce | D4: STALE / RECONCILE REQUIRED | E4: 1191.48 | F4: Undated row in working balance sheet | G4: Verify now | H4: Moises | I4: Balances (Updated 01.01.26) — EA HACKENSACK tab | J4: Check QuickBooks A/P aging/vendor detail and vendor statement | K4: Potential open vendor balance.
A5: Credit Line | B5: BMS Office | C5: Chase LOC | D5: STALE / RECONCILE REQUIRED | E5: 70959.1 | F5: Source dated 2025-09-25 | G5: Verify now | H5: Moises | I5: Balances (Updated 01.01.26) — BMS OFFICE tab | J5: Reconcile to Chase documents + QuickBooks + current statement | K5: Working balance.
A6: Credit Line | B6: Buyahka | C6: First Commerce LOC | D6: STALE / RECONCILE REQUIRED | E6: 371555.65 | F6: Source dated 2025-09-25 | G6: Verify now | H6: Moises | I6: Balances (Updated 01.01.26) — BUYAHKA tab | J6: Reconcile to First Commerce statements/loan docs + QuickBooks | K6: Sheet notes approx. $3,443 available and no principal paid as of source date.
A7: Credit Card | B7: Five Star Bath | C7: Provident + Shell | D7: STALE / RECONCILE REQUIRED | E7: 33664.79 | F7: Source dated 2025-09-25 | G7: Verify now | H7: Moises | I7: Balances (Updated 01.01.26) — FIVE STAR BATH tab | J7: Reconcile cards to statements + QuickBooks | K7: Provident 33,329.67 + Shell 335.12.
A8: A/P | B8: Five Star Bath | C8: Five Star Corp + Tom + WXYZ Scripps | D8: STALE / RECONCILE REQUIRED | E8: 42287.56 | F8: Mixed/older source dates | G8: Verify now | H8: Moises | I8: Balances (Updated 01.01.26) — FIVE STAR BATH tab | J8: Check QuickBooks A/P aging, vendor statements and dispute/payment status | K8: Includes Five Star Corp 22,187.56; accountant 1,500; WXYZ 18,600.
A9: Personal Credit Card | B9: Ahmad Personal / business-use overlap | C9: Capital One cards | D9: STALE / RECONCILE REQUIRED | E9: 51839.37 | F9: Source dated 2025-09-25 | G9: Verify now | H9: Moises + Ahmad | I9: Balances (Updated 01.01.26) — AHMAD PERSONAL tab | J9: Reconcile to current Capital One statements + QuickBooks allocations/reimbursements | K9: Sheet says one card used for Edible; another used for personal and FSBS.
A10: Cash Plan | B10: Buyahka | C10: Sep-Dec 2026 forward cash/distribution plan | D10: ACTIVE WORKING PLAN / VERIFY ACTUALS | E10: See source | F10: Sep-Dec 2026 | G10: Monthly | H10: Moises | I10: Buyahka Compensation | J10: Reconcile actual receipts/payments monthly to bank + QuickBooks | K10: Shows Flower Shop and NY Elevators inflows, recurring property costs, loan payment and planned payments to Ahmad/Hackensack reimbursement.

Sheet HQ_PODCAST
A1: Item ID | B1: Episode / Asset | C1: Stage | D1: Item Type | E1: Owner | F1: Due | G1: Status | H1: Source / Drive Link | I1: Current / Future Use | J1: Publish Target / Platform | K1: Next Action | L1: Notes

Sheet HQ_PERSONAL_REGISTER
A1: Register Type | B1: Item / Account / Policy | C1: Status | D1: Amount | E1: Expected / Renewal / Due | F1: Owner | G1: Source / Evidence | H1: Next Action | I1: Exception? | J1: Notes

Sheet HQ_CUSTOMER_FOLLOWUP
A1: Follow-up ID | B1: Date | C1: Business | D1: Customer / Recipient | E1: Trigger / Segment | F1: Priority | G1: Owner | H1: Due | I1: Status | J1: Next Action | K1: Result | L1: Source / Evidence

Sheet HQ_NOTIFICATION_RULES
A1: Rule ID | B1: Area | C1: Trigger | D1: Severity | E1: Delivery | F1: Recipient / Role | G1: Active? | H1: Last Fired | I1: Notes

Sheet HQ_KSI
A1: Business / Area | B1: Metric / Indicator | C1: Owner | D1: Cadence | E1: Authoritative Source | F1: Threshold / Target | G1: Direction | H1: Current | I1: Status | J1: Last Updated | K1: Next Move

Sheet HQ_GARDENIA_PIPELINE
A1: Account / Prospect | B1: Stage | C1: Contact / Company | D1: Last Contact | E1: Next Follow-up | F1: Tasting / Sample | G1: Standing Cadence | H1: Revenue / Value | I1: Risk | J1: Owner | K1: Source / Evidence | L1: Notes

Sheet HQ_SYSTEM_ACCESS
A1: System / Account | B1: User / Role | C1: Business / Area | D1: Access Level | E1: Owner / Admin | F1: Status | G1: Last Verified | H1: Source / Login Page | I1: Notes

Sheet HQ_GARDENIA_PRODUCT
A1: Product / Test | B1: Standard / Specification | C1: Test Status | D1: Unit Cost | E1: Price | F1: Target Margin | G1: Actual Margin | H1: Open Assumption / Issue | I1: Owner | J1: Source / Evidence | K1: Last Updated

Sheet HQ_CUSTOMER_ISSUES
A1: Date | B1: Week | C1: Year | D1: Business | E1: Issue Type | F1: Customer | G1: Reason / Theme | H1: Amount / Value | I1: Severity | J1: Recovery / Action | K1: Owner | L1: Status | M1: Source / Evidence

Sheet HQ_ACCESS
A1: Email | B1: Name | C1: Role | D1: Area | E1: Active? | F1: Can See All? | G1: Notes
A2: ahmad@wolfventuresnj.com | B2: Ahmad | C2: Executive Owner | D2: All | E2: Yes | F2: Yes | G2: Full owner visibility
A3: emmanuel@wolfventuresnj.com | B3: Emmanuel Nwachukwy | C3: Coordinator / Integrator | D3: Shared Management; Edible; Gardenia's Fire; Finance & Office; Legacy Closeout; Buyahka / Property; People & Systems; Podcast / Legacy; Iron Marks | E3: Yes | F3: No | G3: Multi-area operating access; Personal / Ahmad intentionally excluded.
A4: bookkeeper@wolfventuresnj.com | B4: Moises A. San Miguel | C4: Finance / Bookkeeping | D4: Finance & Office; Edible; Gardenia's Fire; Legacy Closeout; Buyahka / Property | E4: Yes | F4: No | G4: Finance/data/control access; Personal / Ahmad intentionally excluded.

Sheet HQ_CHECKLIST_DEFS
A1: Checklist ID | B1: Business | C1: Area | D1: Checklist Name | E1: Cadence | F1: Owner Role | G1: Required? | H1: Evidence Required? | I1: Active? | J1: Sort
A2: ED-OPEN | B2: Edible | C2: Store | D2: Opening Checklist | E2: DAILY | F2: Store Lead | G2: Yes | H2: No | I2: No | J2: 10
A3: ED-PROD | B3: Edible | C3: Store | D3: Production Readiness | E3: DAILY | F3: Store Lead | G3: Yes | H3: No | I3: No | J3: 20
A4: ED-QA | B4: Edible | C4: Store | D4: Food Safety / Quality | E4: DAILY | F4: Store Lead | G4: Yes | H4: Yes | I4: No | J4: 30
A5: ED-CLEAN | B5: Edible | C5: Store | D5: Cleaning / Sanitation | E5: DAILY | F5: Store Team | G5: Yes | H5: No | I5: No | J5: 40
A6: ED-INV | B6: Edible | C6: Store | D6: Inventory / Supplies | E6: DAILY | F6: Store Lead | G6: Yes | H6: No | I6: No | J6: 50
A7: ED-CUST | B7: Edible | C7: Store | D7: Customer Issues / Guest Connect | E7: DAILY | F7: Store Lead | G7: Yes | H7: Yes | I7: No | J7: 60
A8: ED-CLOSE | B8: Edible | C8: Store | D8: Closing Checklist | E8: DAILY | F8: Store Lead | G8: Yes | H8: Yes | I8: No | J8: 70
A9: ED-WEEK | B9: Edible | C9: Management | D9: Edible Weekly Management Review | E9: WEEKLY | F9: Coordinator | G9: Yes | H9: Yes | I9: No | J9: 100
A10: FI-WEEK | B10: Finance & Office | C10: Management | D10: Finance Week Close | E10: WEEKLY | F10: Finance | G10: Yes | H10: Yes | I10: No | J10: 110
A11: HQ-WEEK | B11: Shared Management | C11: Management | D11: HQ Week Close | E11: WEEKLY | F11: Coordinator | G11: Yes | H11: Yes | I11: Yes | J11: 120
A12: HQ-MONTH | B12: Shared Management | C12: Management | D12: HQ Month Close | E12: MONTHLY | F12: Coordinator | G12: Yes | H12: Yes | I12: Yes | J12: 130
A13: GF-WEEK | B13: Gardenia's Fire | C13: Management | D13: Gardenia Weekly Review | E13: WEEKLY | F13: Coordinator | G13: Yes | H13: Yes | I13: Yes | J13: 140
A14: LC-WEEK | B14: Legacy Closeout | C14: Management | D14: Legacy Closeout Weekly Review | E14: WEEKLY | F14: Coordinator | G14: Yes | H14: Yes | I14: Yes | J14: 150

Sheet HQ_CHECKLIST_ITEMS
A1: Checklist ID | B1: Item ID | C1: Item | D1: Required? | E1: Evidence Required? | F1: Escalate On Fail? | G1: Sort
A2: ED-OPEN | B2: ED-OPEN-01 | C2: Front/store opening condition | D2: Yes | E2: No | F2: Yes | G2: 10
A3: ED-OPEN | B3: ED-OPEN-02 | C3: Phones / tablets / POS ready | D3: Yes | E3: No | F3: Yes | G3: 20
A4: ED-OPEN | B4: ED-OPEN-03 | C4: Fruit / ingredients readiness | D4: Yes | E4: No | F4: Yes | G4: 30
A5: ED-OPEN | B5: ED-OPEN-04 | C5: Production plan reviewed | D5: Yes | E5: No | F5: Yes | G5: 40
A6: ED-OPEN | B6: ED-OPEN-05 | C6: Delivery / pickup schedule reviewed | D6: Yes | E6: No | F6: Yes | G6: 50
A7: ED-OPEN | B7: ED-OPEN-06 | C7: Staff coverage confirmed | D7: Yes | E7: No | F7: Yes | G7: 60
A8: ED-OPEN | B8: ED-OPEN-07 | C8: Cleaning / sanitation opening check | D8: Yes | E8: No | F8: Yes | G8: 70
A9: ED-OPEN | B9: ED-OPEN-08 | C9: Critical supplies available | D9: Yes | E9: No | F9: Yes | G9: 80
A10: ED-PROD | B10: ED-PROD-01 | C10: Orders prioritized by promise time | D10: Yes | E10: No | F10: Yes | G10: 10
A11: ED-PROD | B11: ED-PROD-02 | C11: Fruit prep plan ready | D11: Yes | E11: No | F11: Yes | G11: 20
A12: ED-PROD | B12: ED-PROD-03 | C12: Chocolate / ingredients ready | D12: Yes | E12: No | F12: Yes | G12: 30
A13: ED-PROD | B13: ED-PROD-04 | C13: Packaging / containers ready | D13: Yes | E13: No | F13: Yes | G13: 40
... A92: LC-WEEK | B92: LC-WEEK-06 | C92: Closed items marked closed | D92: Yes | E92: Yes | F92: Yes | G92: 60

Sheet HQ_CHECKLIST_RUNS
A1: Run ID | B1: Checklist ID | C1: Business | D1: Area | E1: Checklist Name | F1: Period Key | G1: Period Type | H1: Scheduled Date | I1: Owner | J1: Status | K1: Required Items | L1: Completed Items | M1: Completion % | N1: On Time? | O1: Exceptions | P1: Evidence Complete? | Q1: Started At | R1: Completed At | S1: Last Update
A2: ED-OPEN-2026-08-30 | B2: ED-OPEN | C2: Edible | D2: Store | E2: Opening Checklist | F2: 46264 | G2: DAILY | H2: 46264 | I2: Store Lead | J2: Not Started | K2: 8 | L2: 0 | M2: 0 | O2: 0 | P2: No | S2: 46264.343
A3: ED-PROD-2026-08-30 | B3: ED-PROD | C3: Edible | D3: Store | E3: Production Readiness | F3: 46264 | G3: DAILY | H3: 46264 | I3: Store Lead | J3: Not Started | K3: 6 | L3: 0 | M3: 0 | O3: 0 | P3: No | S3: 46264.343
A4: ED-QA-2026-08-30 | B4: ED-QA | C4: Edible | D4: Store | E4: Food Safety / Quality | F4: 46264 | G4: DAILY | H4: 46264 | I4: Store Lead | J4: Not Started | K4: 5 | L4: 0 | M4: 0 | O4: 0 | P4: No | S4: 46264.343
A5: ED-CLEAN-2026-08-30 | B5: ED-CLEAN | C5: Edible | D5: Store | E5: Cleaning / Sanitation | F5: 46264 | G5: DAILY | H5: 46264 | I5: Store Team | J5: Not Started | K5: 5 | L5: 0 | M5: 0 | O5: 0 | P5: No | S5: 46264.343
A6: ED-INV-2026-08-30 | B6: ED-INV | C6: Edible | D6: Store | E6: Inventory / Supplies | F6: 46264 | G6: DAILY | H6: 46264 | I6: Store Lead | J6: Not Started | K6: 3 | L6: 0 | M6: 0 | O6: 0 | P6: No | S6: 46264.343
A7: ED-CUST-2026-08-30 | B7: ED-CUST | C7: Edible | D7: Store | E7: Customer Issues / Guest Connect | F7: 46264 | G7: DAILY | H7: 46264 | I7: Store Lead | J7: Not Started | K7: 4 | L7: 0 | M7: 0 | O7: 0 | P7: No | S7: 46264.343
A8: ED-CLOSE-2026-08-30 | B8: ED-CLOSE | C8: Edible | D8: Store | E8: Closing Checklist | F8: 46264 | G8: DAILY | H8: 46264 | I8: Store Lead | J8: Not Started | K8: 7 | L8: 0 | M8: 0 | O8: 0 | P8: No | S8: 46264.343
A9: ED-WEEK-2026-W35 | B9: ED-WEEK | C9: Edible | D9: Management | E9: Edible Weekly Management Review | F9: 2026-W35 | G9: WEEKLY | H9: 46264 | I9: Coordinator | J9: Not Started | K9: 10 | L9: 0 | M9: 0 | O9: 0 | P9: No | S9: 46264.343
A10: FI-WEEK-2026-W35 | B10: FI-WEEK | C10: Finance & Office | D10: Management | E10: Finance Week Close | F10: 2026-W35 | G10: WEEKLY | H10: 46264 | I10: Finance | J10: In Progress | K10: 7 | L10: 2 | M10: 29 | O10: 0 | P10: No | S10: 46264.971
A11: HQ-WEEK-2026-W35 | B11: HQ-WEEK | C11: Shared Management | D11: Management | E11: HQ Week Close | F11: 2026-W35 | G11: WEEKLY | H11: 46264 | I11: Coordinator | J11: Not Started | K11: 10 | L11: 0 | M11: 0 | O11: 0 | P11: No | S11: 46264.343
A12: HQ-MONTH-2026-M08 | B12: HQ-MONTH | C12: Shared Management | D12: Management | E12: HQ Month Close | F12: 2026-M08 | G12: MONTHLY | H12: 46264 | I12: Coordinator | J12: Not Started | K12: 12 | L12: 0 | M12: 0 | O12: 0 | P12: No | S12: 46264.343
A13: GF-WEEK-2026-W35 | B13: GF-WEEK | C13: Gardenia's Fire | D13: Management | E13: Gardenia Weekly Review | F13: 2026-W35 | G13: WEEKLY | H13: 46264 | I13: Coordinator | J13: Not Started | K13: 7 | L13: 0 | M13: 0 | O13: 0 | P13: No | S13: 46264.343
A14: LC-WEEK-2026-W35 | B14: LC-WEEK | C14: Legacy Closeout | D14: Management | E14: Legacy Closeout Weekly Review | F14: 2026-W35 | G14: WEEKLY | H14: 46264 | I14: Coordinator | J14: Not Started | K14: 6 | L14: 0 | M14: 0 | O14: 0 | P14: No | S14: 46264.343

Sheet HQ_TARGETS
A1: Year | B1: Week | C1: Month | D1: Business | E1: Metric | F1: Last Year | G1: Target | H1: Actual | I1: Variance | J1: Variance % | K1: YoY % | L1: Forecast | M1: 4W Trend | N1: YTD Actual | O1: YTD Last Year | P1: YTD Target | Q1: Next Move | R1: Owner | S1: Source

Sheet HQ_BUDGETS
A1: Year | B1: Month | C1: Business | D1: Revenue Budget | E1: Gross Profit Budget | F1: Net Profit Budget | G1: Labor Budget | H1: COGS Budget | I1: Marketing Budget | J1: Other Budget | K1: Money Required | L1: Expected Return | M1: Forecast Revenue | N1: Forecast Net Profit | O1: Owner | P1: Notes

Sheet HQ_CUSTOMERS
A1: Date | B1: Week | C1: Year | D1: Business | E1: Customer | F1: Type | G1: Revenue | H1: Orders | I1: New / Repeat | J1: Recipient? | K1: Recipient Name | L1: Recipient Contactable? | M1: Business Opportunity? | N1: Top Customer? | O1: Relationship Stage | P1: Last Order | Q1: Next Action | R1: Owner | S1: Due | T1: Source / Evidence

Sheet HQ_REVIEWS
A1: Date | B1: Week | C1: Business | D1: Platform | E1: Rating | F1: Review / Issue | G1: Theme | H1: Severity | I1: Response Status | J1: Recovery | K1: Owner | L1: Next Action | M1: Source / Evidence

Sheet HQ_DECISIONS
A1: Decision ID | B1: Date | C1: Business / Area | D1: Decision | E1: Why | F1: Owner | G1: Due | H1: Status | I1: Result / Follow-up | J1: Evidence

Sheet HQ_EXCEPTIONS
A1: Exception ID | B1: Date | C1: Business / Area | D1: Source Type | E1: Source ID | F1: Exception | G1: Severity | H1: Financial Exposure | I1: Owner | J1: Status | K1: Next Action | L1: Due | M1: Age Days | N1: Recurring? | O1: Evidence | P1: Closed Date

Sheet HQ_NOTES
A1: Timestamp | B1: Business / Area | C1: Source Type | D1: Source ID | E1: Note | F1: Author
A2: 46264.949 | B2: Gardenia's fire | C2: IDEA | D2: CAPTURE | E2: Mini Fruit cups | F2: ahmad@wolfventuresnj.com
A3: 46264.949 | B3: Gardenia's fire | C3: IDEA | D3: CAPTURE | E3: Mini Fruit cups | F3: ahmad@wolfventuresnj.com
A4: 46264.949 | B4: Gardenia's fire | C4: IDEA | D4: CAPTURE | E4: Mini Fruit cups | F4: ahmad@wolfventuresnj.com
A5: 46264.949 | B5: Gardenia's fire | C5: IDEA | D5: CAPTURE | E5: Mini Fruit cups | F5: ahmad@wolfventuresnj.com
A6: 46264.949 | B6: Gardenia's fire | C6: IDEA | D6: CAPTURE | E6: Mini Fruit cups | F6: ahmad@wolfventuresnj.com
A7: 46264.949 | B7: Gardenia's fire | C7: IDEA | D7: CAPTURE | E7: Mini Fruit cups | F7: ahmad@wolfventuresnj.com
A8: 46264.95 | B8: Gardenia's fire | C8: IDEA | D8: CAPTURE | E8: Mini Fruit cups | F8: ahmad@wolfventuresnj.com
A9: 46264.95 | B9: Gardenia's fire | C9: IDEA | D9: CAPTURE | E9: Mini Fruit cups | F9: ahmad@wolfventuresnj.com
A10: 46264.95 | B10: Gardenia's fire | C10: IDEA | D10: CAPTURE | E10: Mini Fruit cups | F10: ahmad@wolfventuresnj.com
A11: 46264.97 | C11: Checklist Item | D11: FI-WEEK-2026-W35|FI-WEEK-01 | E11: {"status":"PASS","note":"","evidence":"","updated":"2026-08-31T03:17:21.771Z","user":"ahmad@wolfventuresnj.com"} | F11: ahmad@wolfventuresnj.com
A12: 46264.97 | C12: Checklist Item | D12: FI-WEEK-2026-W35|FI-WEEK-01 | E12: {"status":"PASS","note":"","evidence":"","updated":"2026-08-31T03:17:22.758Z","user":"ahmad@wolfventuresnj.com"} | F12: ahmad@wolfventuresnj.com
A13: 46264.97 | C13: Checklist Item | D13: FI-WEEK-2026-W35|FI-WEEK-02 | E13: {"status":"PASS","note":"","evidence":"","updated":"2026-08-31T03:17:22.928Z","user":"ahmad@wolfventuresnj.com"} | F13: ahmad@wolfventuresnj.com
A14: 46265.066 | B14: Gardenia's fire | C14: IDEA | D14: CAPTURE | E14: Mini Fruit cups | F14: ahmad@wolfventuresnj.com
A15: 46265.066 | B15: Gardenia's fire | C15: IDEA | D15: CAPTURE | E15: Mini Fruit cups | F15: ahmad@wolfventuresnj.com
A16: 46266.539 | B16: My Work | C16: IDEA | D16: CAPTURE | F16: ahmad@wolfventuresnj.com
A17: 46266.539 | B17: My Work | C17: IDEA | D17: CAPTURE | F17: ahmad@wolfventuresnj.com
A18: 46266.539 | B18: My Work | C18: IDEA | D18: CAPTURE | F18: ahmad@wolfventuresnj.com
A19: 46266.539 | B19: My Work | C19: IDEA | D19: CAPTURE | F19: ahmad@wolfventuresnj.com
A20: 46266.539 | B20: My Work | C20: IDEA | D20: CAPTURE | F20: ahmad@wolfventuresnj.com
A21: 46266.539 | B21: My Work | C21: IDEA | D21: CAPTURE | F21: ahmad@wolfventuresnj.com
A22: 46266.539 | B22: My Work | C22: IDEA | D22: CAPTURE | F22: ahmad@wolfventuresnj.com
A23: 46266.539 | B23: My Work | C23: IDEA | D23: CAPTURE | F23: ahmad@wolfventuresnj.com
A24: 46266.539 | B24: My Work | C24: IDEA | D24: CAPTURE | F24: ahmad@wolfventuresnj.com

Sheet HQ_ALERTS
A1: Alert ID | B1: Created | C1: Business / Area | D1: Type | E1: Message | F1: Severity | G1: Owner | H1: Status | I1: Source Type | J1: Source ID | K1: Due | L1: Resolved At
A2: AL-de5dcc2c | B2: 46264.343 | C2: Edible | D2: Incomplete Control | E2: Edible Weekly Management Review is 0% complete | F2: Medium | G2: Coordinator | H2: Open | I2: Checklist Run | J2: ED-WEEK-2026-W35
A3: AL-e65b0945 | B3: 46264.343 | C3: Finance & Office | D3: Incomplete Control | E3: Finance Week Close is 0% complete | F3: Medium | G3: Finance | H3: Open | I3: Checklist Run | J3: FI-WEEK-2026-W35
A4: AL-aaadb52d | B4: 46264.343 | C4: Shared Management | D4: Incomplete Control | E4: HQ Week Close is 0% complete | F4: Medium | G4: Coordinator | H4: Open | I4: Checklist Run | J4: HQ-WEEK-2026-W35
A5: AL-6f1253c8 | B5: 46264.343 | C5: Shared Management | D5: Incomplete Control | E5: HQ Month Close is 0% complete | F5: Medium | G5: Coordinator | H5: Open | I5: Checklist Run | J5: HQ-MONTH-2026-M08
A6: AL-ced04ef5 | B6: 46264.343 | C6: Gardenia's Fire | D6: Incomplete Control | E6: Gardenia Weekly Review is 0% complete | F6: Medium | G6: Coordinator | H6: Open | I6: Checklist Run | J6: GF-WEEK-2026-W35
A7: AL-b0fe3756 | B7: 46264.343 | C7: Legacy Closeout | D7: Incomplete Control | E7: Legacy Closeout Weekly Review is 0% complete | F7: Medium | G7: Coordinator | H7: Open | I7: Checklist Run | J7: LC-WEEK-2026-W35
A8: AL-6f36b4ca | B8: 46264.343 | C8: Edible Operations | D8: Work Exception | E8: Execute labor schedule correction and verify effect needs attention | F8: High | G8: Emmanuel | H8: Open | I8: Work | J8: W-004
A9: AL-7f7f4074 | B9: 46264.343 | C9: Finance & Office | D9: Work Exception | E9: Confirm books/reconciliations/evidence current for weekly close needs attention | F9: High | G9: Moises | H9: Open | I9: Work | J9: W-005
A10: AL-92c3ae02 | B10: 46264.343 | C10: Finance & Office | D10: Work Exception | E10: Review open creditors / obligations with Emmanuel needs attention | F10: High | G10: Moises | H10: Open | I10: Work | J10: W-006
A11: AL-e7327654 | B11: 46264.343 | C11: Ahmad Personal Finance / Life | D11: Work Exception | E11: Establish lightweight personal bills / obligations source map and weekly control needs attention | F11: High | G11: Moises | H11: Open | I11: Work | J11: W-008

Sheet HQ_ACTIVITY
A1: Timestamp | B1: User | C1: Action Type | D1: Business / Area | E1: Source Type | F1: Source ID | G1: Old Value | H1: New Value | I1: Detail
A2: 46264.949 | B2: ahmad@wolfventuresnj.com | C2: NOTE ADDED | D2: Gardenia's fire | E2: IDEA | F2: CAPTURE | H2: Mini Fruit cups
A3: 46264.949 | B3: ahmad@wolfventuresnj.com | C3: NOTE ADDED | D3: Gardenia's fire | E3: IDEA | F3: CAPTURE | H3: Mini Fruit cups
A4: 46264.949 | B4: ahmad@wolfventuresnj.com | C4: NOTE ADDED | D4: Gardenia's fire | E4: IDEA | F4: CAPTURE | H4: Mini Fruit cups
A5: 46264.949 | B5: ahmad@wolfventuresnj.com | C5: NOTE ADDED | D5: Gardenia's fire | E5: IDEA | F5: CAPTURE | H5: Mini Fruit cups
A6: 46264.949 | B6: ahmad@wolfventuresnj.com | C6: NOTE ADDED | D6: Gardenia's fire | E6: IDEA | F6: CAPTURE | H6: Mini Fruit cups
A7: 46264.949 | B7: ahmad@wolfventuresnj.com | C7: NOTE ADDED | D7: Gardenia's fire | E7: IDEA | F7: CAPTURE | H7: Mini Fruit cups
A8: 46264.95 | B8: ahmad@wolfventuresnj.com | C8: NOTE ADDED | D8: Gardenia's fire | E8: IDEA | F8: CAPTURE | H8: Mini Fruit cups
A9: 46264.95 | B9: ahmad@wolfventuresnj.com | C9: NOTE ADDED | D9: Gardenia's fire | E9: IDEA | F9: CAPTURE | H9: Mini Fruit cups
A10: 46264.95 | B10: ahmad@wolfventuresnj.com | C10: NOTE ADDED | D10: Gardenia's fire | E10: IDEA | F10: CAPTURE | H10: Mini Fruit cups
A11: 46264.97 | B11: ahmad@wolfventuresnj.com | C11: CHECKLIST ITEM UPDATE | E11: Checklist Item | F11: FI-WEEK-2026-W35|FI-WEEK-02 | H11: PASS
A12: 46264.971 | B12: ahmad@wolfventuresnj.com | C12: CHECKLIST ITEM UPDATE | E12: Checklist Item | F12: FI-WEEK-2026-W35|FI-WEEK-01 | H12: PASS
A13: 46264.971 | B13: ahmad@wolfventuresnj.com | C13: CHECKLIST ITEM UPDATE | E13: Checklist Item | F13: FI-WEEK-2026-W35|FI-WEEK-01 | H13: PASS
A14: 46265.066 | B14: ahmad@wolfventuresnj.com | C14: NOTE ADDED | D14: Gardenia's fire | E14: IDEA | F14: CAPTURE | H14: Mini Fruit cups
A15: 46265.066 | B15: ahmad@wolfventuresnj.com | C15: NOTE ADDED | D15: Gardenia's fire | E15: IDEA | F15: CAPTURE | H15: Mini Fruit cups
A16: 46266.539 | B16: ahmad@wolfventuresnj.com | C16: NOTE ADDED | D16: My Work | E16: IDEA | F16: CAPTURE
A17: 46266.539 | B17: ahmad@wolfventuresnj.com | C17: NOTE ADDED | D17: My Work | E17: IDEA | F17: CAPTURE
A18: 46266.539 | B18: ahmad@wolfventuresnj.com | C18: NOTE ADDED | D18: My Work | E18: IDEA | F18: CAPTURE
A19: 46266.539 | B19: ahmad@wolfventuresnj.com | C19: NOTE ADDED | D19: My Work | E19: IDEA | F19: CAPTURE
A20: 46266.539 | B20: ahmad@wolfventuresnj.com | C20: NOTE ADDED | D20: My Work | E20: IDEA | F20: CAPTURE
A21: 46266.539 | B21: ahmad@wolfventuresnj.com | C21: NOTE ADDED | D21: My Work | E21: IDEA | F21: CAPTURE
A22: 46266.539 | B22: ahmad@wolfventuresnj.com | C22: NOTE ADDED | D22: My Work | E22: IDEA | F22: CAPTURE
A23: 46266.539 | B23: ahmad@wolfventuresnj.com | C23: NOTE ADDED | D23: My Work | E23: IDEA | F23: CAPTURE
A24: 46266.539 | B24: ahmad@wolfventuresnj.com | C24: NOTE ADDED | D24: My Work | E24: IDEA | F24: CAPTURE
A25: 46266.54 | B25: ahmad@wolfventuresnj.com | C25: WORK CREATED | D25: My Work | E25: Work | F25: W-011 | H25: Open
A26: 46266.54 | B26: ahmad@wolfventuresnj.com | C26: WORK CREATED | D26: My Work | E26: Work | F26: W-012 | H26: Open
A27: 46266.54 | B27: ahmad@wolfventuresnj.com | C27: WORK CREATED | D27: My Work | E27: Work | F27: W-013 | H27: Open
A28: 46266.54 | B28: ahmad@wolfventuresnj.com | C28: WORK CREATED | D28: My Work | E28: Work | F28: W-014 | H28: Open | I28: xfgnxfm
A29: 46266.54 | B29: ahmad@wolfventuresnj.com | C29: WORK CREATED | D29: My Work | E29: Work | F29: W-016 | H29: Open | I29: xfgnxfm
A30: 46266.54 | B30: ahmad@wolfventuresnj.com | C30: WORK CREATED | D30: My Work | E30: Work | F30: W-015 | H30: Open | I30: xfgnxfm
A31: 46266.54 | B31: ahmad@wolfventuresnj.com | C31: WORK CREATED | D31: My Work | E31: Work | F31: W-016 | H31: Open | I31: xfgnxfm
A32: 46266.54 | B32: ahmad@wolfventuresnj.com | C32: WORK CREATED | D32: My Work | E32: Work | F32: W-017 | H32: Open | I32: xfgnxfm

Sheet HQ_LEGACY_CLOSEOUT
A1: Item ID | B1: Old Company / Entity | C1: Creditor / Issue | D1: Amount / Exposure | E1: Stage | F1: Risk | G1: Owner | H1: Next Action | I1: Due | J1: Evidence / Drive Link | K1: Last Update | L1: Closed Date

Sheet HQ_PROPERTY
A1: Property | B1: Category | C1: Item | D1: Status | E1: Amount | F1: Due / Renewal | G1: Owner | H1: Next Action | I1: Source / Evidence | J1: Notes

Sheet HQ_READINESS
A1: Area | B1: System / Source | C1: Status | D1: Authoritative? | E1: Owner | F1: Drive / Source Link | G1: Last Verified | H1: Issue / Next Action
A2: HQ Core | B2: AHMAD HQ — PHASE 1 OPERATING CORE — Sep 2026 | C2: BUILT / STATIC-QA / PARTIALLY POPULATED | D2: Yes for management state; No for underlying transaction truth | E2: Emmanuel / Ahmad | F2: https://docs.google.com/spreadsheets/d/1_zaAT-zqEQhwTW2ZNRLSnH8Peed7zZTzi3kd0RUHQRQ/edit | G2: 2026-09-01 | H2: Harden defects, complete source/readiness wiring, and prove one real multi-user weekly cycle.
A3: HQ Web App | B3: Apps Script two-file deploy build release 1.4.9 | C3: BUILT / DEFECTS / DEPLOYMENT VERSION TO VERIFY | D3: N/A | E3: Technical owner / developer | F3: Drive code artifact 1iulushugXJAhrbP7z4WpMqyFCKo5zFTt | G3: 2026-09-01 | H3: Confirm exact deployed release; fix duplicate writes, #REF!, known UI defects; add locking/idempotency/error logging; regression test and rollback.
A4: Source Governance | B4: HQ_SOURCE_MAP | C4: POPULATING — FIRST VERIFIED PASS COMPLETE | D4: Yes as wiring registry | E4: Emmanuel + source owners | F4: AHMAD HQ Phase 1 Core — HQ_SOURCE_MAP | G4: 2026-09-01 | H4: Verify remaining transactional links, owners, calculations and automation paths before calling production-ready.
A5: Finance & Office | B5: OFFICE FINANCE — LIVE CONTROL SYSTEM — REVISED Aug 2026 | C5: BUILT / STRUCTURE VERIFIED / LIVE USE EARLY | D5: Yes for finance-control status; underlying QuickBooks/banks remain transaction truth | E5: Moises → Emmanuel | F5: https://docs.google.com/spreadsheets/d/1zrY3SOQiF2g8A_7z4ynA9mVnM7_qsvS8eBsebBRplmc/edit | G5: 2026-09-01 | H5: Weekly Review and Phase 1 Verification are mostly NOT STARTED; complete first evidenced close and reconcile source links.
A6: Edible | B6: Edible Hackensack — Store Operations Control System — v3 — Aug 2026 | C6: BUILT / STRUCTURE VERIFIED / ADOPTION EARLY | D6: Yes for operational control; POS/franchise/payroll/accounting are underlying source truth | E6: Store Lead → Emmanuel | F6: https://docs.google.com/spreadsheets/d/1_qBjYd0F4BYYTxLMJjEZbQynBdHH5JGe83-U7nheJOE/edit | G6: 2026-09-01 | H6: Run a complete real Week Close with actual KPIs/evidence; verify no duplicate reporting between Edible and HQ.
A7: Gardenia CRM | B7: HighLevel | C7: PLANNED / NOT WIRED | D7: Planned authoritative relationship/pipeline source | E7: Emmanuel / revenue owner | F7: Not yet verified in HQ | G7: 2026-09-01 | H7: Configure relationship model/pipeline only after launch fields are locked; start simplest integration/export path.
A8: Gardenia Commerce | B8: Shopify | C8: PLANNED / NOT READY | D8: Planned authoritative order/customer commerce source | E8: Emmanuel + Moises | F8: Not yet verified in HQ | G8: 2026-09-01 | H8: Do not custom-build commerce in HQ; configure Shopify and feed management roll-ups when orders begin.
A9: Ironmark | B9: HighLevel + lightweight operating/job records | C9: MODEL VERIFIED / LIVE SYSTEM NOT READY | D9: Planned | E9: Emmanuel / assigned revenue owner | F9: Current model: https://docs.google.com/document/d/1IiSyQbFeaLvEEm2PaktBr5HxhgnDWDN6D9rwvznXZoU/edit | G9: 2026-09-01 | H9: Activate pilot source: lane, providers, leads, completed jobs, economics and QA before adding specialized field-service software.
A10: Permissions | B10: HQ_ACCESS + Apps Script access-control functions | C10: BUILT / NOT LIVE-VERIFIED | D10: Yes for HQ permission policy | E10: Technical owner + Emmanuel | F10: AHMAD HQ Phase 1 Core + deployed web app | G10: 2026-09-01 | H10: Production blocker until role-by-role view/create/edit/close/admin and sensitive-data tests pass.
A11: Reliability | B11: Write/concurrency/error-handling layer | C11: NOT PRODUCTION-HARDENED | D11: N/A | E11: Senior Apps Script engineer | F11: Apps Script deploy code | G11: 2026-09-01 | H11: No LockService found; add locking, idempotency, duplicate-submit protection, centralized error logging and regression tests.
A12: Operating Acceptance | B12: Real multi-user weekly cycle | C12: NOT PROVEN | D12: N/A | E12: Emmanuel + Moises + operating users | F12: HQ + Finance + Edible live systems | G12: 2026-09-01 | H12: Run plan → execute → evidence → exception → review → next plan; measure duplicate entry, chasing, close time, self-management and user friction.
... A20: System Access / Training boundary | B20: HQ_SYSTEM_ACCESS + HQ_TRAINING | C20: SCHEMA ONLY / POPULATE BY EXCEPTION | D20: No for credentials/full training records; yes only for management control state | E20: Emmanuel / system owner | F20: Actual systems, Drive guides, provider/admin records | G20: 2026-09-03 | H20: Do not turn HQ into password vault, LMS, or duplicate access directory. Track only consequential access ownership, missing/disabled access, required capability gap, training exception, backup coverage or control issue.

Sheet HQ_PERIODS
A1: Period Key | B1: Period Type | C1: Year | D1: Week | E1: Month | F1: Start Date | G1: End Date | H1: Status | I1: Completion % | J1: Result Review Complete? | K1: Decision Review Complete? | L1: Next Period Plan Complete? | M1: Closed At | N1: Closed By

Sheet MONTH PLAN
A1: SEPTEMBER 2026 — MONTH PLAN
A5: THIS MONTH MUST PRODUCE
A6: 1. Launch Gardenia's offer and create real local sales activity. 2. Bring Edible labor and sales performance under tighter weekly control. 3. Get Finance / Office weekly close reliable and evidenced. 4. Operate the HQ system through real work, not separate reporting. 5. Protect Ahmad's time for income-producing and high-value work. | H6: SUN | I6: MON | J6: TUE | K6: WED | L6: THU | M6: FRI | N6: SAT
H7: 30 | I7: 31 | J7: 1 | K7: 2 | L7: 3 | M7: 4 | N7: 5
H8: 6 | I8: 7 | J8: 8 | K8: 9 | L8: 10 | M8: 11 | N8: 12
H9: 13 | I9: 14 | J9: 15 | K9: 16 | L9: 17 | M9: 18 | N9: 19
H10: 20 | I10: 21 | J10: 22 | K10: 23 | L10: 24 | M10: 25 | N10: 26
H11: 27 | I11: 28 | J11: 29 | K11: 30 | L11: 1 | M11: 2 | N11: 3
A14: MONTHLY ACTION PLAN — PURPOSE → RESULT → WEEKLY MOVES
A15: FUNCTION / PROJECT | B15: FOCUS | C15: MONTHLY OUTCOME | D15: HOW WE'LL KNOW | E15: OWNER | F15: WEEK 1 MOVE | G15: WEEK 2 | H15: WEEK 3 | I15: WEEK 4 | J15: MONTH-END RESULT / LEARNING
A16: Edible Operations | B16: MAINTAIN | C16: Stabilize store performance while improving labor productivity and sales discipline. | D16: Sales trend; labor %; customer/service exceptions; Week Close reliability. | E16: Emmanuel / Store | F16: Labor correction + marketing execution
A17: Gardenia's Fire | B17: PUSH | C17: Move from preparation into actual local sales activity and first standing accounts. | D17: Prospects; calls; tastings; standing accounts; weekly revenue. | E17: Emmanuel | F17: Product/cost + target list + outreach
A18: Finance & Office | B18: PUSH | C18: Create reliable weekly financial visibility with evidence and no silent material issues. | D18: Books current; reconciliations; A/P/A/R reviewed; evidence complete; exceptions assigned. | E18: Moises → Emmanuel | F18: Complete first clean weekly close
A19: Podcast / Legacy | B19: PUSH | C19: Keep production moving from script/recording through review/edit/retain. | D19: Recordings reviewed; edits moved; useful material retained. | E19: Ahmad + Emmanuel | F19: Move current video/editor to next executable step
A20: People / Systems | B20: MAINTAIN | C20: Make roles, schedules, priorities and follow-through visible without duplicate reporting. | D20: Owners clear; Viane placement resolved; weekly rhythm actually used. | E20: Emmanuel | F20: Run system from real work; confirm capacity
A21: Ahmad Personal Finance / Life | B21: PUSH | C21: Gain compressed visibility of personal obligations, recurring charges and decisions without another bureaucracy. | D21: Bills/obligations visible; recurring charges reviewed; exceptions escalated. | E21: Moises / Emmanuel / Ahmad | F21: Establish source map + weekly review
A24: MONTH CLOSE — DID THE MONTH ACTUALLY MOVE THE BUSINESS?
A25: DONE? | B25: CLOSE QUESTION | C25: OWNER | D25: RESULT / EXCEPTION / LEARNING
A26: FALSE | B26: Were the month's most important outcomes materially advanced or closed? | C26: Emmanuel / Ahmad
A27: FALSE | B27: Did Edible's sales/labor/customer picture improve, deteriorate or stay flat — and why? | C27: Emmanuel
A28: FALSE | B28: Did Gardenia's produce real market activity and conversion learning? | C28: Emmanuel
A29: FALSE | B29: Is Finance / Office more current, evidenced and exception-driven than at month start? | C29: Moises / Emmanuel
A30: FALSE | B30: Did this operating system reduce memory dependence and duplicate reporting? | C30: Emmanuel / Ahmad
A31: FALSE | B31: What should be PUSH / MAINTAIN / PARK next month? | C31: Ahmad

Sheet THIS WEEK
A1: THIS WEEK — EXECUTION BOARD
A3: Week of Aug 31–Sep 4 • Finish meaningful outcomes, not administrative theater
A5: ="OPEN CRITICAL MOVES"&CHAR(10)&COUNTIFS('WORK DESK — UPDATE'!G:G,"Yes",'WORK DESK — UPDATE'!J:J,"<>Done",'WORK DESK — UPDATE'!J:J,"<>Dropped") -> OPEN CRITICAL MOVES 6 | D5: ="RESULT-PRODUCING"&CHAR(10)&COUNTIFS('WORK DESK — UPDATE'!H:H,"Yes",'WORK DESK — UPDATE'!J:J,"<>Done",'WORK DESK — UPDATE'!J:J,"<>Dropped") -> RESULT-PRODUCING 10 | G5: ="WAITING / BLOCKED"&CHAR(10)&(COUNTIF('WORK DESK — UPDATE'!J:J,"Waiting")+COUNTIF('WORK DESK — UPDATE'!J:J,"Blocked")+COUNTIF('WORK DESK — UPDATE'!L:L,"Yes")) -> WAITING / BLOCKED 0 | J5: ="AHMAD DECISIONS"&CHAR(10)&COUNTIF('06_DECISIONS'!G:G,"Open") -> AHMAD DECISIONS 1
A9: WEEKLY OUTCOMES / CRITICAL MOVES
A10: PROJECT / FUNCTION | B10: NEXT ACTION | C10: OWNER | D10: FOCUS | E10: DUE | F10: STATUS | G10: WAITING ON | H10: ESCALATE?
A11: =IFERROR(__xludf.DUMMYFUNCTION("IFERROR(FILTER(HSTACK('WORK DESK — UPDATE'!B6:B120,'WORK DESK — UPDATE'!C6:C120,'WORK DESK — UPDATE'!D6:D120,'WORK DESK — UPDATE'!F6:F120,'WORK DESK — UPDATE'!I6:I120,'WORK DESK — UPDATE'!J6:J120,'WORK DESK — UPDATE'!K6:K120,'WORK DESK — UPDATE'!Q6:Q120),"&"'WORK DESK — UPDATE'!G6:G120=""Yes"",'WORK DESK — UPDATE'!J6:J120<>""Done"",'WORK DESK — UPDATE'!J6:J120<>""Dropped""),""No open critical moves"")"),"Gardenia's Fire") -> Gardenia's Fire | B11: =IFERROR(__xludf.DUMMYFUNCTION("""COMPUTED_VALUE"""),"Confirm sellable offer is ready from Emmanuel's real-life process; capture only price/cost/margin or constraints needed for selling/management") -> Confirm sellable offer is ready from Emmanuel's real-life process; capture only price/cost/margin or constraints needed for selling/management | C11: =IFERROR(__xludf.DUMMYFUNCTION("""COMPUTED_VALUE"""),"Emmanuel") -> Emmanuel | D11: =IFERROR(__xludf.DUMMYFUNCTION("""COMPUTED_VALUE"""),"PUSH") -> PUSH | E11: =IFERROR(__xludf.DUMMYFUNCTION("""COMPUTED_VALUE"""),46265.0) -> 46265 | F11: =IFERROR(__xludf.DUMMYFUNCTION("""COMPUTED_VALUE"""),"In Progress") -> In Progress | H11: =IFERROR(__xludf.DUMMYFUNCTION("""COMPUTED_VALUE"""),"No") -> No
A12: =IFERROR(__xludf.DUMMYFUNCTION("""COMPUTED_VALUE"""),"Gardenia's Fire") -> Gardenia's Fire | B12: =IFERROR(__xludf.DUMMYFUNCTION("""COMPUTED_VALUE"""),"Build/confirm target account list") -> Build/confirm target account list | C12: =IFERROR(__xludf.DUMMYFUNCTION("""COMPUTED_VALUE"""),"Emmanuel") -> Emmanuel | D12: =IFERROR(__xludf.DUMMYFUNCTION("""COMPUTED_VALUE"""),"PUSH") -> PUSH | E12: =IFERROR(__xludf.DUMMYFUNCTION("""COMPUTED_VALUE"""),46266.0) -> 46266 | F12: =IFERROR(__xludf.DUMMYFUNCTION("""COMPUTED_VALUE"""),"Open") -> Open | H12: =IFERROR(__xludf.DUMMYFUNCTION("""COMPUTED_VALUE"""),"No") -> No
A13: =IFERROR(__xludf.DUMMYFUNCTION("""COMPUTED_VALUE"""),"Gardenia's Fire") -> Gardenia's Fire | B13: =IFERROR(__xludf.DUMMYFUNCTION("""COMPUTED_VALUE"""),"Begin outreach and schedule tastings") -> Begin outreach and schedule tastings | C13: =IFERROR(__xludf.DUMMYFUNCTION("""COMPUTED_VALUE"""),"Emmanuel") -> Emmanuel | D13: =IFERROR(__xludf.DUMMYFUNCTION("""COMPUTED_VALUE"""),"PUSH") -> PUSH | E13: =IFERROR(__xludf.DUMMYFUNCTION("""COMPUTED_VALUE"""),46269.0) -> 46269 | F13: =IFERROR(__xludf.DUMMYFUNCTION("""COMPUTED_VALUE"""),"Open") -> Open | H13: =IFERROR(__xludf.DUMMYFUNCTION("""COMPUTED_VALUE"""),"No") -> No
